<?xml version="1.0" ?>
<!-- =================================================================================== -->
<!-- |    This document was autogenerated by xacro from /home/johnnylin/slam_project/src/robot_description/urdf/xacro/big_car.urdf.xacro | -->
<!-- |    EDITING THIS FILE BY HAND IS NOT RECOMMENDED                                 | -->
<!-- =================================================================================== -->
<!-- 组合小车底盘与摄像头与雷达 -->
<robot name="big_car">
  <!-- 宏:黑色设置 -->
  <material name="black">
    <color rgba="0.0 0.0 0.0 1.0"/>
  </material>
  <!-- 质量  -->
  <!-- 底盘 -->
  <link name="base_footprint">
    <visual>
      <geometry>
        <sphere radius="0.001"/>
      </geometry>
    </visual>
  </link>
  <link name="base_link">
    <visual>
      <geometry>
        <cylinder length="0.08" radius="0.1"/>
      </geometry>
      <origin rpy="0 0 0" xyz="0 0 0"/>
      <material name="yellow">
        <color rgba="0.5 0.3 0.0 0.5"/>
      </material>
    </visual>
    <collision>
      <geometry>
        <cylinder length="0.08" radius="0.1"/>
      </geometry>
      <origin rpy="0 0 0" xyz="0 0 0"/>
    </collision>
    <inertial>
      <mass value="0.5"/>
      <inertia ixx="0.001516666666666667" ixy="0" ixz="0" iyy="0.001516666666666667" iyz="0" izz="0.0025000000000000005"/>
    </inertial>
  </link>
  <joint name="base_link2base_footprint" type="fixed">
    <parent link="base_footprint"/>
    <child link="base_link"/>
    <origin xyz="0 0 0.055"/>
  </joint>
  <gazebo reference="base_link">
    <material>Gazebo/Yellow</material>
  </gazebo>
  <!-- 质量  -->
  <link name="left_wheel">
    <visual>
      <geometry>
        <cylinder length="0.015" radius="0.0325"/>
      </geometry>
      <origin rpy="1.5707963 0.0 0.0" xyz="0.0 0.0 0.0"/>
      <material name="black"/>
    </visual>
    <collision>
      <geometry>
        <cylinder length="0.015" radius="0.0325"/>
      </geometry>
      <origin rpy="1.5707963 0.0 0.0" xyz="0.0 0.0 0.0"/>
    </collision>
    <inertial>
      <mass value="0.05"/>
      <inertia ixx="1.4140625000000002e-05" ixy="0" ixz="0" iyy="1.4140625000000002e-05" iyz="0" izz="2.6406250000000005e-05"/>
    </inertial>
  </link>
  <joint name="left_wheel2base_link" type="continuous">
    <parent link="base_link"/>
    <child link="left_wheel"/>
    <origin xyz="0 0.1 -0.0225"/>
    <axis xyz="0 1 0"/>
  </joint>
  <gazebo reference="left_wheel">
    <material>Gazebo/Red</material>
  </gazebo>
  <link name="right_wheel">
    <visual>
      <geometry>
        <cylinder length="0.015" radius="0.0325"/>
      </geometry>
      <origin rpy="1.5707963 0.0 0.0" xyz="0.0 0.0 0.0"/>
      <material name="black"/>
    </visual>
    <collision>
      <geometry>
        <cylinder length="0.015" radius="0.0325"/>
      </geometry>
      <origin rpy="1.5707963 0.0 0.0" xyz="0.0 0.0 0.0"/>
    </collision>
    <inertial>
      <mass value="0.05"/>
      <inertia ixx="1.4140625000000002e-05" ixy="0" ixz="0" iyy="1.4140625000000002e-05" iyz="0" izz="2.6406250000000005e-05"/>
    </inertial>
  </link>
  <joint name="right_wheel2base_link" type="continuous">
    <parent link="base_link"/>
    <child link="right_wheel"/>
    <origin xyz="0 -0.1 -0.0225"/>
    <axis xyz="0 1 0"/>
  </joint>
  <gazebo reference="right_wheel">
    <material>Gazebo/Red</material>
  </gazebo>
  <!-- 质量  -->
  <link name="front_wheel">
    <visual>
      <geometry>
        <sphere radius="0.0075"/>
      </geometry>
      <origin rpy="0 0 0" xyz="0 0 0"/>
      <material name="black"/>
    </visual>
    <collision>
      <geometry>
        <sphere radius="0.0075"/>
      </geometry>
      <origin rpy="0 0 0" xyz="0 0 0"/>
    </collision>
    <inertial>
      <mass value="0.03"/>
      <inertia ixx="6.75e-07" ixy="0" ixz="0" iyy="6.75e-07" iyz="0" izz="6.75e-07"/>
    </inertial>
  </link>
  <joint name="front_wheel2base_link" type="continuous">
    <parent link="base_link"/>
    <child link="front_wheel"/>
    <origin xyz="0.0925 0 -0.0475"/>
    <axis xyz="1 1 1"/>
  </joint>
  <gazebo reference="front_wheel">
    <material>Gazebo/Red</material>
  </gazebo>
  <link name="back_wheel">
    <visual>
      <geometry>
        <sphere radius="0.0075"/>
      </geometry>
      <origin rpy="0 0 0" xyz="0 0 0"/>
      <material name="black"/>
    </visual>
    <collision>
      <geometry>
        <sphere radius="0.0075"/>
      </geometry>
      <origin rpy="0 0 0" xyz="0 0 0"/>
    </collision>
    <inertial>
      <mass value="0.03"/>
      <inertia ixx="6.75e-07" ixy="0" ixz="0" iyy="6.75e-07" iyz="0" izz="6.75e-07"/>
    </inertial>
  </link>
  <joint name="back_wheel2base_link" type="continuous">
    <parent link="base_link"/>
    <child link="back_wheel"/>
    <origin xyz="-0.0925 0 -0.0475"/>
    <axis xyz="1 1 1"/>
  </joint>
  <gazebo reference="back_wheel">
    <material>Gazebo/Red</material>
  </gazebo>
  <!-- 摄像头安装的z坐标:底盘高度 / 2 + 摄像头高度 / 2  -->
  <!-- 摄像头质量 -->
  <!-- 摄像头关节以及link -->
  <link name="camera">
    <visual>
      <geometry>
        <box size="0.01 0.025 0.025"/>
      </geometry>
      <origin rpy="0.0 0.0 0.0" xyz="0.0 0.0 0.0"/>
      <material name="black"/>
    </visual>
    <collision>
      <geometry>
        <box size="0.01 0.025 0.025"/>
      </geometry>
      <origin rpy="0.0 0.0 0.0" xyz="0.0 0.0 0.0"/>
    </collision>
    <inertial>
      <mass value="0.01"/>
      <inertia ixx="6.041666666666668e-07" ixy="0" ixz="0" iyy="6.041666666666668e-07" iyz="0" izz="1.041666666666667e-06"/>
    </inertial>
  </link>
  <joint name="camera2base_link" type="fixed">
    <parent link="base_link"/>
    <child link="camera"/>
    <origin xyz="0.08 0.0 0.052500000000000005"/>
  </joint>
  <gazebo reference="camera">
    <material>Gazebo/Blue</material>
  </gazebo>
  <!-- 支架质量 -->
  <link name="support">
    <visual>
      <geometry>
        <cylinder length="0.15" radius="0.01"/>
      </geometry>
      <origin rpy="0.0 0.0 0.0" xyz="0.0 0.0 0.0"/>
      <material name="red">
        <color rgba="0.8 0.2 0.0 0.8"/>
      </material>
    </visual>
    <collision>
      <geometry>
        <cylinder length="0.15" radius="0.01"/>
      </geometry>
      <origin rpy="0.0 0.0 0.0" xyz="0.0 0.0 0.0"/>
    </collision>
    <inertial>
      <mass value="0.02"/>
      <inertia ixx="3.8e-05" ixy="0" ixz="0" iyy="3.8e-05" iyz="0" izz="1.0000000000000002e-06"/>
    </inertial>
  </link>
  <joint name="support2base_link" type="fixed">
    <parent link="base_link"/>
    <child link="support"/>
    <origin xyz="0.0 0.0 0.11499999999999999"/>
  </joint>
  <gazebo reference="support">
    <material>Gazebo/White</material>
  </gazebo>
  <!-- Lidar质量 -->
  <!-- 3D Lidar关节以及link -->
  <link name="lidar">
    <visual>
      <geometry>
        <cylinder length="0.1" radius="0.05"/>
      </geometry>
      <origin rpy="0.0 0.0 0.0" xyz="0.0 0.0 0.0"/>
      <material name="black"/>
    </visual>
    <collision>
      <geometry>
        <cylinder length="0.1" radius="0.05"/>
      </geometry>
      <origin rpy="0.0 0.0 0.0" xyz="0.0 0.0 0.0"/>
    </collision>
    <inertial>
      <mass value="0.2"/>
      <inertia ixx="0.0002916666666666667" ixy="0" ixz="0" iyy="0.0002916666666666667" iyz="0" izz="0.00025000000000000006"/>
    </inertial>
  </link>
  <joint name="lidar2support" type="fixed">
    <parent link="support"/>
    <child link="lidar"/>
    <origin xyz="0.0 0.0 0.125"/>
  </joint>
  <gazebo reference="lidar">
    <material>Gazebo/Black</material>
  </gazebo>
  <!-- 3D Lidar传感器插件 -->
  <gazebo>
    <sensor name="lidar_sensor" type="gpu_ray">
      <update_rate>10</update_rate>
      <ray>
        <scan>
          <horizontal>
            <samples>640</samples>
            <resolution>1</resolution>
            <min_angle>-3.14</min_angle>
            <max_angle>3.14</max_angle>
          </horizontal>
          <vertical>
            <samples>32</samples>
            <resolution>1</resolution>
            <min_angle>-0.25</min_angle>
            <max_angle>0.25</max_angle>
          </vertical>
        </scan>
        <range>
          <min>0.1</min>
          <max>30.0</max>
          <resolution>0.01</resolution>
        </range>
        <noise>
          <type>gaussian</type>
          <mean>0.0</mean>
          <stddev>0.01</stddev>
        </noise>
      </ray>
      <plugin filename="libgazebo_ros_gpu_laser.so" name="gazebo_ros_gpu_laser">
        <topicName>/lidar_points</topicName>
        <frameName>lidar_link</frameName>
      </plugin>
    </sensor>
  </gazebo>
  <!-- Transmission is important to link the joints and the controller -->
  <transmission name="left_wheel2base_link_trans">
    <type>transmission_interface/SimpleTransmission</type>
    <joint name="left_wheel2base_link">
      <hardwareInterface>hardware_interface/VelocityJointInterface</hardwareInterface>
    </joint>
    <actuator name="left_wheel2base_link_motor">
      <hardwareInterface>hardware_interface/VelocityJointInterface</hardwareInterface>
      <mechanicalReduction>1</mechanicalReduction>
    </actuator>
  </transmission>
  <!-- Transmission is important to link the joints and the controller -->
  <transmission name="right_wheel2base_link_trans">
    <type>transmission_interface/SimpleTransmission</type>
    <joint name="right_wheel2base_link">
      <hardwareInterface>hardware_interface/VelocityJointInterface</hardwareInterface>
    </joint>
    <actuator name="right_wheel2base_link_motor">
      <hardwareInterface>hardware_interface/VelocityJointInterface</hardwareInterface>
      <mechanicalReduction>1</mechanicalReduction>
    </actuator>
  </transmission>
  <!-- 控制器 -->
  <gazebo>
    <plugin filename="libgazebo_ros_diff_drive.so" name="differential_drive_controller">
      <rosDebugLevel>Debug</rosDebugLevel>
      <publishWheelTF>true</publishWheelTF>
      <robotNamespace>/</robotNamespace>
      <publishTf>1</publishTf>
      <publishWheelJointState>true</publishWheelJointState>
      <alwaysOn>true</alwaysOn>
      <updateRate>100.0</updateRate>
      <legacyMode>true</legacyMode>
      <leftJoint>left_wheel2base_link</leftJoint>
      <!-- 左轮 -->
      <rightJoint>right_wheel2base_link</rightJoint>
      <!-- 右轮 -->
      <wheelSeparation>0.2</wheelSeparation>
      <!-- 车轮间距 -->
      <wheelDiameter>0.065</wheelDiameter>
      <!-- 车轮直径 -->
      <broadcastTF>1</broadcastTF>
      <wheelTorque>30</wheelTorque>
      <wheelAcceleration>1.8</wheelAcceleration>
      <commandTopic>cmd_vel</commandTopic>
      <!-- 运动控制话题 -->
      <odometryFrame>odom</odometryFrame>
      <odometryTopic>odom</odometryTopic>
      <!-- 里程计话题 -->
      <robotBaseFrame>base_footprint</robotBaseFrame>
      <!-- 根坐标系 -->
    </plugin>
  </gazebo>
</robot>
